<mujoco model="dexterous_emergency_kit_lab">
  <compiler angle="degree" meshdir="assets"/>
  <option timestep="0.002" integrator="RK4" gravity="0 0 -9.81" iterations="100"/>
  <visual><global offwidth="1280" offheight="720"/></visual>
  <default>
    <joint damping="1.0" armature="0.02"/>
    <geom friction="8 5 0.6" solref="0.005 1" solimp="0.99 0.99 0.001"/>
  </default>
  <worldbody>
    <light pos="0 -3 4" dir="0 1 -1"/>
    <camera name="overhead" pos="0.35 0 3.2" xyaxes="1 0 0 0 1 0"/>
    <camera name="side" pos="0.35 -2.2 0.7" xyaxes="1 0 0 0 0 1"/>
    <camera name="closeup" mode="targetbody" target="medicine_cap" pos="0.35 0.25 0.28"/>

    <geom name="table" type="box" size="0.75 0.45 0.03" pos="0.35 0 0.02" rgba="0.12 0.14 0.16 1"/>
    <geom name="pill_tray" type="box" size="0.15 0.12 0.015" pos="0.15 -0.15 0.075" rgba="0.6 0.6 0.65 1"/>

    <body name="pill_red" pos="0.18 -0.15 0.11">
      <joint name="pill_red_f" type="free" damping="0.2"/>
      <geom type="sphere" size="0.016" rgba="1 0.2 0.2 1" mass="0.003"/>
    </body>
    <body name="pill_blue" pos="0.12 -0.15 0.11">
      <joint name="pill_blue_f" type="free" damping="0.2"/>
      <geom type="sphere" size="0.016" rgba="0.2 0.4 1 1" mass="0.003"/>
    </body>

    <body name="kit_box" pos="0.72 -0.12 0.06">
      <geom name="kit_base" type="box" size="0.16 0.11 0.025" pos="0 0 0.025" rgba="0.08 0.4 0.85 1"/>
      <geom type="box" size="0.06 0.09 0.018" pos="-0.05 0 0.04" rgba="0.15 0.45 0.85 0.7"/>
      <geom type="box" size="0.025 0.09 0.018" pos="0.07 0 0.04" rgba="0.15 0.45 0.85 0.7"/>
      <body name="kit_lid" pos="0 0 0.05">
        <joint name="lid_hinge" type="hinge" axis="0 1 0" range="0 90" damping="0.5"/>
        <geom name="lid_geom" type="box" size="0.16 0.11 0.01" pos="0 0 0.01" rgba="0.9 0.85 0.8 1"/>
        <site name="lid_touch_site" pos="0.08 0 0.015" size="0.008" type="sphere" rgba="0 1 0 0.4"/>
      </body>
    </body>

    <body name="medicine_vial" pos="0.25 0.10 0.13">
      <joint name="vial_free" type="free" damping="0.15"/>
      <geom name="vial_body" type="cylinder" size="0.035 0.075" rgba="0.9 0.9 0.95 1" mass="0.05" friction="12 8 0.8"/>
    </body>

    <body name="medicine_cap" pos="0.25 0.10 0.21">
      <joint name="cap_free" type="free" damping="0.3"/>
      <geom name="cap_geom" type="cylinder" size="0.037 0.015" rgba="0.9 0.25 0.2 1" mass="0.008" friction="12 8 0.6"/>
      <geom type="box" size="0.037 0.004 0.016" pos="0 0 0" rgba="0.75 0.15 0.1 1"/>
      <geom type="box" size="0.004 0.037 0.016" pos="0 0 0" rgba="0.75 0.15 0.1 1"/>
      <geom name="cap_notch" type="box" size="0.012 0.008 0.022" pos="0.030 -0.022 0" rgba="1 0.95 0.2 1"/>
      <geom name="cap_notch2" type="box" size="0.006 0.006 0.020" pos="-0.028 0.020 0" rgba="0.2 1 0.9 1"/>
    </body>

    <body name="syringe" pos="0.50 0.18 0.10">
      <joint name="syringe_free" type="free" damping="0.18"/>
      <geom type="capsule" fromto="-0.06 0 0 0.06 0 0" size="0.011" rgba="0.85 0.95 1 1" mass="0.02" friction="12 8 0.6"/>
    </body>

    <!-- 5-finger hand with SPHERE TIPS for contact grasping -->
    <body name="dex_hand_base" pos="0.04 0.0 0.18">
      <joint name="arm_x" type="slide" axis="1 0 0" range="0 0.9"/>
      <joint name="arm_y" type="slide" axis="0 1 0" range="-0.3 0.3"/>
      <joint name="arm_z" type="slide" axis="0 0 1" range="-0.15 0.3"/>
      <joint name="wrist_yaw" type="hinge" axis="0 0 1" range="-45 45" damping="0.4"/>
      <joint name="wrist_pitch" type="hinge" axis="0 1 0" range="-45 45" damping="0.4"/>
      <geom type="box" size="0.055 0.035 0.025" rgba="0.75 0.55 0.45 1"/>
      <site name="palm_site" pos="0.055 0 0" size="0.025" type="sphere" rgba="0 1 0 0.25"/>

      <body name="thumb" pos="0.04 -0.035 0">
        <joint name="thumb_abd" type="hinge" axis="0 0 1" range="-35 35"/>
        <geom type="capsule" fromto="0 0 0 .055 -.035 0" size=".009" friction="15 10 0.8"/>
        <body pos=".055 -.035 0">
          <joint name="thumb_pip" type="hinge" axis="0 1 0" range="0 90"/>
          <geom type="capsule" fromto="0 0 0 .04 0 0" size=".008" friction="15 10 0.8"/>
          <geom name="thumb_tip" type="sphere" pos=".04 0 0" size=".018" rgba="0.85 0.7 0.6 0.6" friction="20 15 0.8"/>
        </body>
      </body>

      <body name="index" pos="0.055 -0.018 0">
        <joint name="index_mcp" type="hinge" axis="0 1 0" range="0 100"/>
        <geom type="capsule" fromto="0 0 0 .07 0 0" size=".008" friction="15 10 0.8"/>
        <body pos=".07 0 0">
          <joint name="index_pip" type="hinge" axis="0 1 0" range="0 100"/>
          <geom type="capsule" fromto="0 0 0 .045 0 0" size=".007" friction="15 10 0.8"/>
          <geom name="index_tip" type="sphere" pos=".045 0 0" size=".018" rgba="0.85 0.7 0.6 0.6" friction="20 15 0.8"/>
          <site name="index_tip_site" pos=".045 0 0" size=".006" type="sphere" rgba="0 1 0 .35"/>
        </body>
      </body>

      <body name="middle" pos="0.06 0 0">
        <joint name="middle_mcp" type="hinge" axis="0 1 0" range="0 100"/>
        <geom type="capsule" fromto="0 0 0 .078 0 0" size=".008" friction="15 10 0.8"/>
        <body pos=".078 0 0">
          <joint name="middle_pip" type="hinge" axis="0 1 0" range="0 100"/>
          <geom type="capsule" fromto="0 0 0 .048 0 0" size=".007" friction="15 10 0.8"/>
          <geom name="middle_tip" type="sphere" pos=".048 0 0" size=".018" rgba="0.85 0.7 0.6 0.6" friction="20 15 0.8"/>
          <site name="middle_tip_site" pos=".048 0 0" size=".006" type="sphere" rgba="0 1 0 .35"/>
        </body>
      </body>

      <body name="ring" pos="0.055 0.018 0">
        <joint name="ring_mcp" type="hinge" axis="0 1 0" range="0 100"/>
        <geom type="capsule" fromto="0 0 0 .07 0 0" size=".008" friction="15 10 0.8"/>
        <body pos=".07 0 0">
          <joint name="ring_pip" type="hinge" axis="0 1 0" range="0 100"/>
          <geom type="capsule" fromto="0 0 0 .043 0 0" size=".007" friction="15 10 0.8"/>
          <geom name="ring_tip" type="sphere" pos=".043 0 0" size=".018" rgba="0.85 0.7 0.6 0.6" friction="20 15 0.8"/>
        </body>
      </body>

      <body name="little" pos="0.05 0.035 0">
        <joint name="little_mcp" type="hinge" axis="0 1 0" range="0 100"/>
        <geom type="capsule" fromto="0 0 0 .06 0 0" size=".007" friction="15 10 0.8"/>
        <body pos=".06 0 0">
          <joint name="little_pip" type="hinge" axis="0 1 0" range="0 100"/>
          <geom type="capsule" fromto="0 0 0 .038 0 0" size=".006" friction="15 10 0.8"/>
          <geom name="little_tip" type="sphere" pos=".038 0 0" size=".018" rgba="0.85 0.7 0.6 0.6" friction="20 15 0.8"/>
        </body>
      </body>
    </body>
  </worldbody>
  <actuator>
    <position joint="arm_x" kp="220"/><position joint="arm_y" kp="220"/><position joint="arm_z" kp="220"/>
    <position joint="wrist_yaw" kp="35"/><position joint="wrist_pitch" kp="35"/>
    <position joint="thumb_abd" kp="15"/><position joint="thumb_pip" kp="15"/>
    <position joint="index_mcp" kp="15"/><position joint="index_pip" kp="15"/>
    <position joint="middle_mcp" kp="15"/><position joint="middle_pip" kp="15"/>
    <position joint="ring_mcp" kp="15"/><position joint="ring_pip" kp="15"/>
    <position joint="little_mcp" kp="15"/><position joint="little_pip" kp="15"/>
  </actuator>
  <sensor>
    <touch name="palm_touch" site="palm_site"/>
    <touch name="index_tip_touch" site="index_tip_site"/>
    <touch name="middle_tip_touch" site="middle_tip_site"/>
    <touch name="lid_touch" site="lid_touch_site"/>
    <jointpos name="arm_x_pos" joint="arm_x"/><jointpos name="arm_y_pos" joint="arm_y"/><jointpos name="arm_z_pos" joint="arm_z"/>
    <jointpos name="wrist_yaw_pos" joint="wrist_yaw"/><jointpos name="wrist_pitch_pos" joint="wrist_pitch"/>
    <jointpos name="thumb_abd_pos" joint="thumb_abd"/><jointpos name="thumb_pip_pos" joint="thumb_pip"/>
    <jointpos name="index_mcp_pos" joint="index_mcp"/><jointpos name="index_pip_pos" joint="index_pip"/>
    <jointpos name="middle_mcp_pos" joint="middle_mcp"/><jointpos name="middle_pip_pos" joint="middle_pip"/>
    <jointpos name="ring_mcp_pos" joint="ring_mcp"/><jointpos name="ring_pip_pos" joint="ring_pip"/>
    <jointpos name="little_mcp_pos" joint="little_mcp"/><jointpos name="little_pip_pos" joint="little_pip"/>
  </sensor>
</mujoco>
